Workbook

Sheet 01_Raw_Data
A1: id | B1: first_name | C1: last_name | D1: email | E1: gender | F1: part_time_job | G1: absence_days | H1: extracurricular_activities | I1: weekly_self_study_hours | J1: career_aspiration | K1: math_score | L1: history_score | M1: physics_score | N1: chemistry_score | O1: biology_score | P1: english_score | Q1: geography_score
A2: 1 | B2: Paul | C2: Casey | D2: paul.casey.1@gslingacademy.com | E2: male | F2: FALSE | G2: 3 | H2: FALSE | I2: 27 | J2: Lawyer | K2: 73 | L2: 81 | M2: 93 | N2: 97 | O2: 63 | P2: 80 | Q2: 87
A3: 2 | B3: Danielle | C3: Sandoval | D3: danielle.sandoval.2@gslingacademy.com | E3: female | F3: FALSE | G3: 2 | H3: FALSE | I3: 47 | J3: Doctor | K3: 90 | L3: 86 | M3: 96 | N3: 100 | O3: 90 | P3: 88 | Q3: 90
A4: 3 | B4: Tina | C4: Andrews | D4: tina.andrews.3@gslingacademy.com | E4: female | F4: FALSE | G4: 9 | H4: TRUE | I4: 13 | J4: Government Officer | K4: 81 | L4: 97 | M4: 95 | N4: 96 | O4: 65 | P4: 77 | Q4: 94
A5: 4 | B5: Tara | C5: Clark | D5: tara.clark.4@gslingacademy.com | E5: female | F5: FALSE | G5: 5 | H5: FALSE | I5: 3 | J5: Artist | K5: 71 | L5: 74 | M5: 88 | N5: 80 | O5: 89 | P5: 63 | Q5: 86
A6: 5 | B6: Anthony | C6: Campos | D6: anthony.campos.5@gslingacademy.com | E6: male | F6: FALSE | G6: 5 | H6: FALSE | I6: 10 | J6: Social Network Studies | K6: 84 | L6: 77 | M6: 65 | N6: 65 | O6: 80 | P6: 74 | Q6: 76
A7: 6 | B7: Kelly | C7: Wade | D7: kelly.wade.6@gslingacademy.com | E7: female | F7: FALSE | G7: 2 | H7: FALSE | I7: 26 | J7: Social Network Studies | K7: 93 | L7: 100 | M7: 67 | N7: 78 | O7: 72 | P7: 80 | Q7: 84
A8: 7 | B8: Anthony | C8: Smith | D8: anthony.smith.7@gslingacademy.com | E8: male | F8: FALSE | G8: 3 | H8: TRUE | I8: 23 | J8: Software Engineer | K8: 99 | L8: 96 | M8: 97 | N8: 73 | O8: 88 | P8: 76 | Q8: 64
A9: 8 | B9: George | C9: Short | D9: george.short.8@gslingacademy.com | E9: male | F9: TRUE | G9: 2 | H9: TRUE | I9: 34 | J9: Software Engineer | K9: 95 | L9: 95 | M9: 82 | N9: 63 | O9: 84 | P9: 70 | Q9: 85
A10: 9 | B10: Stanley | C10: Gutierrez | D10: stanley.gutierrez.9@gslingacademy.com | E10: male | F10: FALSE | G10: 6 | H10: FALSE | I10: 25 | J10: Social Network Studies | K10: 94 | L10: 68 | M10: 94 | N10: 85 | O10: 81 | P10: 74 | Q10: 72
A11: 10 | B11: Audrey | C11: Simpson | D11: audrey.simpson.10@gslingacademy.com | E11: female | F11: FALSE | G11: 3 | H11: TRUE | I11: 18 | J11: Teacher | K11: 98 | L11: 69 | M11: 88 | N11: 71 | O11: 67 | P11: 71 | Q11: 73
A12: 11 | B12: Gabrielle | C12: White | D12: gabrielle.white.11@gslingacademy.com | E12: female | F12: FALSE | G12: 2 | H12: FALSE | I12: 7 | J12: Teacher | K12: 65 | L12: 60 | M12: 97 | N12: 94 | O12: 71 | P12: 81 | Q12: 66
A13: 12 | B13: Clinton | C13: Randolph | D13: clinton.randolph.12@gslingacademy.com | E13: male | F13: FALSE | G13: 1 | H13: FALSE | I13: 7 | J13: Social Network Studies | K13: 80 | L13: 61 | M13: 100 | N13: 65 | O13: 87 | P13: 64 | Q13: 61
... A6001: 6000 | B6001: Natalie | C6001: Smith | D6001: natalie.smith.2000@gslingacademy.com | E6001: female | F6001: FALSE | G6001: 5 | H6001: FALSE | I6001: 27 | J6001: Accountant | K6001: 82 | L6001: 99 | M6001: 91 | N6001: 69 | O6001: 83 | P6001: 93 | Q6001: 100

Sheet 02_Data_Cleaning
A1: gender | B1: part_time_job | C1: absence_days | D1: extracurricular_activities | E1: weekly_self_study_hours | F1: career_aspiration | G1: math_score | H1: history_score | I1: physics_score | J1: chemistry_score | K1: biology_score | L1: english_score | M1: geography_score | N1: gender_numeric | O1: part_time_numeric | P1: extracurricular_numeric | Q1: career_category | R1: stem | S1: science_average
A2: male | B2: FALSE | C2: 3 | D2: FALSE | E2: 27 | F2: Lawyer | G2: 73 | H2: 81 | I2: 93 | J2: 97 | K2: 63 | L2: 80 | M2: 87 | N2: =IF(A2="Male",1,0) -> 1 | O2: =IF(B2=FALSE,0,1) -> 0 | P2: =IF(D2=FALSE,0,1) -> 0 | Q2: =IF(OR(F2="Software Engineer",F2="Scientist",F2="Construction Engineer",F2="Game Developer",F2="Doctor"),"STEM","Non-STEM") -> Non-STEM | R2: =IF(Q2="STEM",1,0) -> 0 | S2: =AVERAGE(G2,I2,J2,K2) -> 81.5
A3: female | B3: FALSE | C3: 2 | D3: FALSE | E3: 47 | F3: Doctor | G3: 90 | H3: 86 | I3: 96 | J3: 100 | K3: 90 | L3: 88 | M3: 90 | N3: =IF(A3="Male",1,0) -> 0 | O3: =IF(B3=FALSE,0,1) -> 0 | P3: =IF(D3=FALSE,0,1) -> 0 | Q3: =IF(OR(F3="Software Engineer",F3="Scientist",F3="Construction Engineer",F3="Game Developer",F3="Doctor"),"STEM","Non-STEM") -> STEM | R3: =IF(Q3="STEM",1,0) -> 1 | S3: =AVERAGE(G3,I3,J3,K3) -> 94
A4: female | B4: FALSE | C4: 9 | D4: TRUE | E4: 13 | F4: Government Officer | G4: 81 | H4: 97 | I4: 95 | J4: 96 | K4: 65 | L4: 77 | M4: 94 | N4: =IF(A4="Male",1,0) -> 0 | O4: =IF(B4=FALSE,0,1) -> 0 | P4: =IF(D4=FALSE,0,1) -> 1 | Q4: =IF(OR(F4="Software Engineer",F4="Scientist",F4="Construction Engineer",F4="Game Developer",F4="Doctor"),"STEM","Non-STEM") -> Non-STEM | R4: =IF(Q4="STEM",1,0) -> 0 | S4: =AVERAGE(G4,I4,J4,K4) -> 84.25
A5: female | B5: FALSE | C5: 5 | D5: FALSE | E5: 3 | F5: Artist | G5: 71 | H5: 74 | I5: 88 | J5: 80 | K5: 89 | L5: 63 | M5: 86 | N5: =IF(A5="Male",1,0) -> 0 | O5: =IF(B5=FALSE,0,1) -> 0 | P5: =IF(D5=FALSE,0,1) -> 0 | Q5: =IF(OR(F5="Software Engineer",F5="Scientist",F5="Construction Engineer",F5="Game Developer",F5="Doctor"),"STEM","Non-STEM") -> Non-STEM | R5: =IF(Q5="STEM",1,0) -> 0 | S5: =AVERAGE(G5,I5,J5,K5) -> 82
A6: male | B6: FALSE | C6: 5 | D6: FALSE | E6: 10 | F6: Social Network Studies | G6: 84 | H6: 77 | I6: 65 | J6: 65 | K6: 80 | L6: 74 | M6: 76 | N6: =IF(A6="Male",1,0) -> 1 | O6: =IF(B6=FALSE,0,1) -> 0 | P6: =IF(D6=FALSE,0,1) -> 0 | Q6: =IF(OR(F6="Software Engineer",F6="Scientist",F6="Construction Engineer",F6="Game Developer",F6="Doctor"),"STEM","Non-STEM") -> Non-STEM | R6: =IF(Q6="STEM",1,0) -> 0 | S6: =AVERAGE(G6,I6,J6,K6) -> 73.5
A7: female | B7: FALSE | C7: 2 | D7: FALSE | E7: 26 | F7: Social Network Studies | G7: 93 | H7: 100 | I7: 67 | J7: 78 | K7: 72 | L7: 80 | M7: 84 | N7: =IF(A7="Male",1,0) -> 0 | O7: =IF(B7=FALSE,0,1) -> 0 | P7: =IF(D7=FALSE,0,1) -> 0 | Q7: =IF(OR(F7="Software Engineer",F7="Scientist",F7="Construction Engineer",F7="Game Developer",F7="Doctor"),"STEM","Non-STEM") -> Non-STEM | R7: =IF(Q7="STEM",1,0) -> 0 | S7: =AVERAGE(G7,I7,J7,K7) -> 77.5
A8: male | B8: FALSE | C8: 3 | D8: TRUE | E8: 23 | F8: Software Engineer | G8: 99 | H8: 96 | I8: 97 | J8: 73 | K8: 88 | L8: 76 | M8: 64 | N8: =IF(A8="Male",1,0) -> 1 | O8: =IF(B8=FALSE,0,1) -> 0 | P8: =IF(D8=FALSE,0,1) -> 1 | Q8: =IF(OR(F8="Software Engineer",F8="Scientist",F8="Construction Engineer",F8="Game Developer",F8="Doctor"),"STEM","Non-STEM") -> STEM | R8: =IF(Q8="STEM",1,0) -> 1 | S8: =AVERAGE(G8,I8,J8,K8) -> 89.25
A9: male | B9: TRUE | C9: 2 | D9: TRUE | E9: 34 | F9: Software Engineer | G9: 95 | H9: 95 | I9: 82 | J9: 63 | K9: 84 | L9: 70 | M9: 85 | N9: =IF(A9="Male",1,0) -> 1 | O9: =IF(B9=FALSE,0,1) -> 1 | P9: =IF(D9=FALSE,0,1) -> 1 | Q9: =IF(OR(F9="Software Engineer",F9="Scientist",F9="Construction Engineer",F9="Game Developer",F9="Doctor"),"STEM","Non-STEM") -> STEM | R9: =IF(Q9="STEM",1,0) -> 1 | S9: =AVERAGE(G9,I9,J9,K9) -> 81
A10: male | B10: FALSE | C10: 6 | D10: FALSE | E10: 25 | F10: Social Network Studies | G10: 94 | H10: 68 | I10: 94 | J10: 85 | K10: 81 | L10: 74 | M10: 72 | N10: =IF(A10="Male",1,0) -> 1 | O10: =IF(B10=FALSE,0,1) -> 0 | P10: =IF(D10=FALSE,0,1) -> 0 | Q10: =IF(OR(F10="Software Engineer",F10="Scientist",F10="Construction Engineer",F10="Game Developer",F10="Doctor"),"STEM","Non-STEM") -> Non-STEM | R10: =IF(Q10="STEM",1,0) -> 0 | S10: =AVERAGE(G10,I10,J10,K10) -> 88.5
A11: female | B11: FALSE | C11: 3 | D11: TRUE | E11: 18 | F11: Teacher | G11: 98 | H11: 69 | I11: 88 | J11: 71 | K11: 67 | L11: 71 | M11: 73 | N11: =IF(A11="Male",1,0) -> 0 | O11: =IF(B11=FALSE,0,1) -> 0 | P11: =IF(D11=FALSE,0,1) -> 1 | Q11: =IF(OR(F11="Software Engineer",F11="Scientist",F11="Construction Engineer",F11="Game Developer",F11="Doctor"),"STEM","Non-STEM") -> Non-STEM | R11: =IF(Q11="STEM",1,0) -> 0 | S11: =AVERAGE(G11,I11,J11,K11) -> 81
A12: female | B12: FALSE | C12: 2 | D12: FALSE | E12: 7 | F12: Teacher | G12: 65 | H12: 60 | I12: 97 | J12: 94 | K12: 71 | L12: 81 | M12: 66 | N12: =IF(A12="Male",1,0) -> 0 | O12: =IF(B12=FALSE,0,1) -> 0 | P12: =IF(D12=FALSE,0,1) -> 0 | Q12: =IF(OR(F12="Software Engineer",F12="Scientist",F12="Construction Engineer",F12="Game Developer",F12="Doctor"),"STEM","Non-STEM") -> Non-STEM | R12: =IF(Q12="STEM",1,0) -> 0 | S12: =AVERAGE(G12,I12,J12,K12) -> 81.75
A13: male | B13: FALSE | C13: 1 | D13: FALSE | E13: 7 | F13: Social Network Studies | G13: 80 | H13: 61 | I13: 100 | J13: 65 | K13: 87 | L13: 64 | M13: 61 | N13: =IF(A13="Male",1,0) -> 1 | O13: =IF(B13=FALSE,0,1) -> 0 | P13: =IF(D13=FALSE,0,1) -> 0 | Q13: =IF(OR(F13="Software Engineer",F13="Scientist",F13="Construction Engineer",F13="Game Developer",F13="Doctor"),"STEM","Non-STEM") -> Non-STEM | R13: =IF(Q13="STEM",1,0) -> 0 | S13: =AVERAGE(G13,I13,J13,K13) -> 83
... A2001: female | B2001: FALSE | C2001: 5 | D2001: FALSE | E2001: 27 | F2001: Accountant | G2001: 82 | H2001: 99 | I2001: 91 | J2001: 69 | K2001: 83 | L2001: 93 | M2001: 100 | N2001: =IF(A2001="Male",1,0) -> 0 | O2001: =IF(B2001=FALSE,0,1) -> 0 | P2001: =IF(D2001=FALSE,0,1) -> 0 | Q2001: =IF(OR(F2001="Software Engineer",F2001="Scientist",F2001="Construction Engineer",F2001="Game Developer",F2001="Doctor"),"STEM","Non-STEM") -> Non-STEM | R2001: =IF(Q2001="STEM",1,0) -> 0 | S2001: =AVERAGE(G2001,I2001,J2001,K2001) -> 81.25

Sheet 03_Descriptive_Statistics
A1: absence_days | F1: weekly_self_study_hours | K1: science_average
A2: Mean | B2: =AVERAGE('02_Data_Cleaning'!C:C) -> 3.6655 | F2: Mean | G2: =AVERAGE('02_Data_Cleaning'!E:E) -> 17.7555 | K2: Mean | L2: =AVERAGE('02_Data_Cleaning'!S:S) -> 81.09125
A3: Median | B3: =MEDIAN('02_Data_Cleaning'!C:C) -> 3 | F3: Median | G3: =MEDIAN('02_Data_Cleaning'!E:E) -> 18 | K3: Median | L3: =MEDIAN('02_Data_Cleaning'!S:S) -> 81.375
A4: St_dev | B4: =_xlfn.STDEV.S('02_Data_Cleaning'!C:C) -> 2.6292711 | F4: St_dev | G4: =_xlfn.STDEV.S('02_Data_Cleaning'!E:E) -> 12.129604 | K4: St_dev | L4: =_xlfn.STDEV.S('02_Data_Cleaning'!S:S) -> 7.5935584
A5: Q1 | B5: =_xlfn.QUARTILE.EXC('02_Data_Cleaning'!C:C,1) -> 2 | F5: Q1 | G5: =_xlfn.QUARTILE.EXC('02_Data_Cleaning'!E:E,1) -> 5 | K5: Q1 | L5: =_xlfn.QUARTILE.EXC('02_Data_Cleaning'!S:S,1) -> 76.25
A6: Q3 | B6: =_xlfn.QUARTILE.EXC('02_Data_Cleaning'!C:C,3) -> 5 | F6: Q3 | G6: =_xlfn.QUARTILE.EXC('02_Data_Cleaning'!E:E,3) -> 28 | K6: Q3 | L6: =_xlfn.QUARTILE.EXC('02_Data_Cleaning'!S:S,3) -> 86.5
A7: IQR | B7: =B6-B5 -> 3 | F7: IQR | G7: =G6-G5 -> 23 | K7: IQR | L7: =L6-L5 -> 10.25
A8: Lower_fence | B8: =B5-1.5*B7 -> -2.5 | F8: Lower_fence | G8: =G5-1.5*G7 -> -29.5 | K8: Lower_fence | L8: =L5-1.5*L7 -> 60.875
A9: Upper_fence | B9: =B6+1.5*B7 -> 9.5 | F9: Upper_fence | G9: =G6+1.5*G7 -> 62.5 | K9: Upper_fence | L9: =L6+1.5*L7 -> 101.875
A10: Min | B10: =MIN('02_Data_Cleaning'!C:C) -> 0 | F10: Min | G10: =MIN('02_Data_Cleaning'!E:E) -> 0 | K10: Min | L10: =MIN('02_Data_Cleaning'!S:S) -> 51.5
A11: Max | B11: =MAX('02_Data_Cleaning'!C:C) -> 10 | F11: Max | G11: =MAX('02_Data_Cleaning'!E:E) -> 50 | K11: Max | L11: =MAX('02_Data_Cleaning'!S:S) -> 97.5

Sheet 04_Group_Summary
A2: Gender | B2: Count | C2: Percentage | D2: Average of Science Average | E2: Average of Study Hours
A3: female | B3: 1002 | C3: 0.501 | D3: 80.767465 | E3: 16.822355 | I3: Males log slightly more study hours per week (18.69 vs. 16.82)
A4: male | B4: 998 | C4: 0.499 | D4: 81.416333 | E4: 18.692385 | I4: with a marginally higher science average (81.42 vs. 80.77)
A5: Total | B5: 2000 | C5: 1 | D5: 81.09125 | E5: 17.7555
A9: Part-time Job | B9: Count | C9: Percentage | D9: Average of Science Average | E9: Average of Study Hours
A10: FALSE | B10: 1684 | C10: 0.842 | D10: 81.654691 | E10: 18.879454 | I10: Working students average 7 fewer study hours per week
A11: TRUE | B11: 316 | C11: 0.158 | D11: 78.088608 | E11: 11.765823 | I11: (11.77 hrs vs. 18.88 hrs) and have lower science averages (78.09 vs. 81.65)
A12: Total | B12: 2000 | C12: 1 | D12: 81.09125 | E12: 17.7555
A16: Extracurriculum | B16: Count | C16: Percentage | D16: Average of Science Average | E16: Average of Study Hours
A17: FALSE | B17: 1592 | C17: 0.796 | D17: 81.217023 | E17: 18.077889 | I17: Students without extracurriculars log about 1.5 more study hours
A18: TRUE | B18: 408 | C18: 0.204 | D18: 80.60049 | E18: 16.497549 | I18: (18.08 vs. 16.50) with a slightly higher score (81.22 vs. 80.60)
A19: Total | B19: 2000 | C19: 1 | D19: 81.09125 | E19: 17.7555
A23: Career Aspire | B23: Count | C23: Percentage | D23: Average of Science Average | E23: Average of Study Hours | F23: StDev of science_average | G23: StdDev of self_study | I23: Students aiming for STEM careers study nearly 10 hours more per week
A24: Non-STEM | B24: 1396 | C24: 0.698 | D24: 79.049427 | E24: 14.743553 | F24: 7.3188684 | G24: 11.321189 | I24: (24.72 hrs vs. 14.74 hrs) and achieve a significantly higher science average (85.81 vs. 79.05).
A25: STEM | B25: 604 | C25: 0.302 | D25: 85.81043 | E25: 24.716887 | F25: 5.9392718 | G25: 11.031132 | I25: Based on Standard Deviation, Science Average scores among STEM students are more consistent,
A26: Total | B26: 2000 | C26: 1 | D26: 81.09125 | E26: 17.7555 | F26: 7.5935584 | G26: 12.129604 | I26: while Non-STEM students show greater variability in their performance. Both groups show a
I27: similar level of variability in their study habits despite having different average study hours.
E32: The dataset contains 2,000 students. Approximately 49% are male and 50% are female.
E33: Most students do not have a part-time job, also a majority don't participate in extracurricular activities.
E34: Additionally, the dataset includes students aspiring to Non-STEM careers more than at STEM careers.

Sheet 05_EDA
B20: This histogram shows the distribution of students' Science Average scores. Most students are concentrated | M20: While our scatter plot reveals a clear positive trend between study hours and science scores, there is noticeable vertical
B21: around the center of the distribution, while relatively few students have very low or very high Science Average values. | M21: dispersion around the regression line (R^2 = 0.1811). This residual spread indicates that study hours alone leave 81.89%
M22: of the variation in grades unexplained. Each point represents one student. The graph allows us to visually examine whether
M23: students who study more hours tend to achieve higher Science Average scores.
B50: The comparison between STEM and Non-STEM students showed that students aspiring to STEM careers | M50: This scatter plot illustrates the negative relationship between student absenteeism and academic outcome
B51: achieved a higher mean Science Average than students aspiring to Non-STEM | M51: As anticipated, the trendline slopes downward: each missed day inflicts an average penalty of -0.68 points
M52: on a student's science average from an ideal baseline of 83.59 points. With an R^2 of 0.0556, absence days account
M53: for 5.56% of score variation, confirming that absenteeism acts as a modest but steady drag on academic performance
G56: absence_days | H56: weekly_self_study_hours | I56: gender_numeric | J56: part_time_numeric | K56: extracurricular_numeric
F57: absence_days | G57: 1
F58: weekly_self_study_hours | G58: -0.28608562 | H58: 1
F59: gender_numeric | G59: -0.029357359 | H59: 0.077104474 | I59: 1
F60: part_time_numeric | G60: 0.20636066 | H60: -0.21396262 | I60: -0.023808723 | J60: 1
F61: extracurricular_numeric | G61: 0.029018652 | H61: -0.052515108 | I61: -0.0064322697 | J61: -0.0083821321 | K61: 1
F62: science_average | G62: -0.23579802 | H62: 0.42555502 | I62: 0.04273547 | J62: -0.17133235 | K62: -0.03272584 | L62: 1
F65: The correlation matrix showed that Weekly Self-Study Hours had a positive correlation with Science Average,
F66: while Absence Days showed a negative correlation. The remaining variables demonstrated weaker relationships.

Sheet 06_Hypothesis_Testing
A1: career_category | B1: science_average | C1: nonstem-avg | D1: stem-avg | H1: H0 | I1: Students aspiring to STEM careers have the same average Science Average as students aspiring to Non-STEM careers. | S1: Refuzohet
A2: Non-STEM | B2: 81.5 | C2: =IF(A2="Non-STEM",B2,"") -> 81.5 | D2: =IF(A2="STEM",B2,"") | H2: HA | I2: Students aspiring to STEM careers have a different average Science Average than students aspiring to Non-STEM careers. | S2: Pranohet
A3: STEM | B3: 94 | C3: =IF(A3="Non-STEM",B3,"") | D3: =IF(A3="STEM",B3,"") -> 94
A4: Non-STEM | B4: 84.25 | C4: =IF(A4="Non-STEM",B4,"") -> 84.25 | D4: =IF(A4="STEM",B4,"") | J4: STEM CALC | N4: Non-STEM CALC
A5: Non-STEM | B5: 82 | C5: =IF(A5="Non-STEM",B5,"") -> 82 | D5: =IF(A5="STEM",B5,"") | J5: stemmean | K5: =AVERAGE(D:D) -> 85.81043 | N5: nonstemmean | O5: =AVERAGE(C:C) -> 79.049427
A6: Non-STEM | B6: 73.5 | C6: =IF(A6="Non-STEM",B6,"") -> 73.5 | D6: =IF(A6="STEM",B6,"") | J6: stdev | K6: =_xlfn.STDEV.S(D:D) -> 5.9392718 | N6: stdev | O6: =_xlfn.STDEV.S(C:C) -> 7.3188684
A7: Non-STEM | B7: 77.5 | C7: =IF(A7="Non-STEM",B7,"") -> 77.5 | D7: =IF(A7="STEM",B7,"") | J7: obv | K7: =COUNT(D:D) -> 604 | N7: obv | O7: =COUNT(C:C) -> 1396
A8: STEM | B8: 89.25 | C8: =IF(A8="Non-STEM",B8,"") | D8: =IF(A8="STEM",B8,"") -> 89.25 | J8: var | K8: =POWER(K6,2) -> 35.274949 | L8: p-value | M8: ? | N8: var | O8: =POWER(O6,2) -> 53.565835
A9: STEM | B9: 81 | C9: =IF(A9="Non-STEM",B9,"") | D9: =IF(A9="STEM",B9,"") -> 81 | L9: degoffr | M9: ?
A10: Non-STEM | B10: 88.5 | C10: =IF(A10="Non-STEM",B10,"") -> 88.5 | D10: =IF(A10="STEM",B10,"") | L10: t | M10: =(K5-O5)/(SQRT((POWER(K6,2)/K7)+(POWER(O6,2)/O7))) -> 21.7337
A11: Non-STEM | B11: 81 | C11: =IF(A11="Non-STEM",B11,"") -> 81 | D11: =IF(A11="STEM",B11,"")
A12: Non-STEM | B12: 81.75 | C12: =IF(A12="Non-STEM",B12,"") -> 81.75 | D12: =IF(A12="STEM",B12,"")
A13: Non-STEM | B13: 83 | C13: =IF(A13="Non-STEM",B13,"") -> 83 | D13: =IF(A13="STEM",B13,"")
A14: Non-STEM | B14: 79.75 | C14: =IF(A14="Non-STEM",B14,"") -> 79.75 | D14: =IF(A14="STEM",B14,"") | K14: with t.test | L14: =_xlfn.T.TEST(D:D,C:C,2,3) -> 1.9256379e-90
A15: Non-STEM | B15: 77.25 | C15: =IF(A15="Non-STEM",B15,"") -> 77.25 | D15: =IF(A15="STEM",B15,"")
A16: STEM | B16: 91.5 | C16: =IF(A16="Non-STEM",B16,"") | D16: =IF(A16="STEM",B16,"") -> 91.5
A17: Non-STEM | B17: 78.75 | C17: =IF(A17="Non-STEM",B17,"") -> 78.75 | D17: =IF(A17="STEM",B17,"") | J17: PJESA1 | K17: =POWER(K6,2) -> 35.274949 | M17: PJESA2 | N17: =POWER(O6,2) -> 53.565835
A18: STEM | B18: 89 | C18: =IF(A18="Non-STEM",B18,"") | D18: =IF(A18="STEM",B18,"") -> 89 | J18: PJESA1.2 | K18: =K17/K7 -> 0.058402234 | M18: PJESA2.2 | N18: =N17/O7 -> 0.038370942
A19: STEM | B19: 85.75 | C19: =IF(A19="Non-STEM",B19,"") | D19: =IF(A19="STEM",B19,"") -> 85.75 | L19: =K18+N18 -> 0.096773175
A20: STEM | B20: 95 | C20: =IF(A20="Non-STEM",B20,"") | D20: =IF(A20="STEM",B20,"") -> 95 | K20: NUMERUESIFINAL | L20: =POWER(L19,2) -> 0.0093650475
A21: STEM | B21: 84.5 | C21: =IF(A21="Non-STEM",B21,"") | D21: =IF(A21="STEM",B21,"") -> 84.5
A22: STEM | B22: 85.75 | C22: =IF(A22="Non-STEM",B22,"") | D22: =IF(A22="STEM",B22,"") -> 85.75
A23: Non-STEM | B23: 78 | C23: =IF(A23="Non-STEM",B23,"") -> 78 | D23: =IF(A23="STEM",B23,"") | J23: PJESA3 | K23: =POWER(K18,2) -> 0.0034108209 | M23: PJESA4 | N23: =POWER(N18,2) -> 0.0014723292
A24: Non-STEM | B24: 75 | C24: =IF(A24="Non-STEM",B24,"") -> 75 | D24: =IF(A24="STEM",B24,"") | J24: PJESA3.2 | K24: =K7-1 -> 603 | M24: PJESA4.2 | N24: =O7-1 -> 1395
A25: Non-STEM | B25: 60.5 | C25: =IF(A25="Non-STEM",B25,"") -> 60.5 | D25: =IF(A25="STEM",B25,"") | J25: PJESA3.3 | K25: =K23/K24 -> 5.6564194e-06 | M25: PJESA4.3 | N25: =N23/N24 -> 1.0554331e-06
A26: STEM | B26: 90 | C26: =IF(A26="Non-STEM",B26,"") | D26: =IF(A26="STEM",B26,"") -> 90 | K26: EMERUESIFINAL | L26: =K25+N25 -> 6.7118525e-06
A27: STEM | B27: 88.25 | C27: =IF(A27="Non-STEM",B27,"") | D27: =IF(A27="STEM",B27,"") -> 88.25
A28: Non-STEM | B28: 84.25 | C28: =IF(A28="Non-STEM",B28,"") -> 84.25 | D28: =IF(A28="STEM",B28,"") | K28: degoffr | L28: =L20/L26 -> 1395.3
A29: Non-STEM | B29: 79.25 | C29: =IF(A29="Non-STEM",B29,"") -> 79.25 | D29: =IF(A29="STEM",B29,"") | K29: p-value | L29: =_xlfn.T.DIST.2T(M10,L28) -> 1.9368903e-90
A30: Non-STEM | B30: 81.25 | C30: =IF(A30="Non-STEM",B30,"") -> 81.25 | D30: =IF(A30="STEM",B30,"")
A31: Non-STEM | B31: 67.5 | C31: =IF(A31="Non-STEM",B31,"") -> 67.5 | D31: =IF(A31="STEM",B31,"") | I31: Since the p-value is less than the significance level of 0.05, the null hypothesis (H₀) is rejected. Therefore, there is statistically significant
A32: STEM | B32: 90.75 | C32: =IF(A32="Non-STEM",B32,"") | D32: =IF(A32="STEM",B32,"") -> 90.75 | I32: evidence that students aspiring to STEM careers have a different average Science Average than students aspiring to Non-STEM careers.
A33: Non-STEM | B33: 79.5 | C33: =IF(A33="Non-STEM",B33,"") -> 79.5 | D33: =IF(A33="STEM",B33,"")
A34: Non-STEM | B34: 87.25 | C34: =IF(A34="Non-STEM",B34,"") -> 87.25 | D34: =IF(A34="STEM",B34,"")
A35: Non-STEM | B35: 84.75 | C35: =IF(A35="Non-STEM",B35,"") -> 84.75 | D35: =IF(A35="STEM",B35,"")
A36: Non-STEM | B36: 86.75 | C36: =IF(A36="Non-STEM",B36,"") -> 86.75 | D36: =IF(A36="STEM",B36,"")
A37: Non-STEM | B37: 80.25 | C37: =IF(A37="Non-STEM",B37,"") -> 80.25 | D37: =IF(A37="STEM",B37,"")
A38: STEM | B38: 86.5 | C38: =IF(A38="Non-STEM",B38,"") | D38: =IF(A38="STEM",B38,"") -> 86.5
A39: STEM | B39: 86.75 | C39: =IF(A39="Non-STEM",B39,"") | D39: =IF(A39="STEM",B39,"") -> 86.75
A40: Non-STEM | B40: 80.75 | C40: =IF(A40="Non-STEM",B40,"") -> 80.75 | D40: =IF(A40="STEM",B40,"")
...

Sheet 07_MLR
A1: absence_days | B1: weekly_self_study_hours | C1: gender_numeric | D1: part_time_numeric | E1: extracurricular_numeric | F1: science_average
A2: 3 | B2: 27 | C2: 1 | D2: 0 | E2: 0 | F2: 81.5
A3: 2 | B3: 47 | C3: 0 | D3: 0 | E3: 0 | F3: 94
A4: 9 | B4: 13 | C4: 0 | D4: 0 | E4: 1 | F4: 84.25
A5: 5 | B5: 3 | C5: 0 | D5: 0 | E5: 0 | F5: 82
A6: 5 | B6: 10 | C6: 1 | D6: 0 | E6: 0 | F6: 73.5
A7: 2 | B7: 26 | C7: 0 | D7: 0 | E7: 0 | F7: 77.5
A8: 3 | B8: 23 | C8: 1 | D8: 0 | E8: 1 | F8: 89.25
A9: 2 | B9: 34 | C9: 1 | D9: 1 | E9: 1 | F9: 81
A10: 6 | B10: 25 | C10: 1 | D10: 0 | E10: 0 | F10: 88.5
A11: 3 | B11: 18 | C11: 0 | D11: 0 | E11: 1 | F11: 81
A12: 2 | B12: 7 | C12: 0 | D12: 0 | E12: 0 | F12: 81.75
A13: 1 | B13: 7 | C13: 1 | D13: 0 | E13: 0 | F13: 83
... A2001: 5 | B2001: 27 | C2001: 0 | D2001: 0 | E2001: 0 | F2001: 81.25
A2006: SUMMARY OUTPUT
A2008: Regression Statistics
A2009: Multiple R | B2009: 0.4467684
A2010: R Square | B2010: 0.199602
A2011: Adjusted R Square | B2011: 0.19759499
A2012: Standard Error | B2012: 6.8020866
A2013: Observations | B2013: 2000
A2015: ANOVA
B2016: df | C2016: SS | D2016: MS | E2016: F | F2016: Significance F
A2017: Regression | B2017: 5 | C2017: 23007.444 | D2017: 4601.4887 | E2017: 99.452121 | F2017: 8.3976957e-94
A2018: Residual | B2018: 1994 | C2018: 92259.153 | D2018: 46.268382
A2019: Total | B2019: 1999 | C2019: 115266.6
B2021: Coefficients | C2021: Standard Error | D2021: t Stat | E2021: P-value | F2021: Lower 95% | G2021: Upper 95% | H2021: Lower 95.0% | I2021: Upper 95.0%
A2022: Intercept | B2022: 78.288654 | C2022: 0.43277592 | D2022: 180.89882 | E2022: 0 | F2022: 77.439913 | G2022: 79.137394 | H2022: 77.439913 | I2022: 79.137394
A2023: absence_days | B2023: -0.32751263 | C2023: 0.061137443 | D2023: -5.3569893 | E2023: 9.4395259e-08 | F2023: -0.4474126 | G2023: -0.20761266 | H2023: -0.4474126 | I2023: -0.20761266
A2024: weekly_self_study_hours | B2024: 0.23637549 | C2024: 0.013320543 | D2024: 17.745185 | E2024: 1.5700985e-65 | F2024: 0.21025185 | G2024: 0.26249913 | H2024: 0.21025185 | I2024: 0.26249913
A2025: gender_numeric | B2025: 0.1310744 | C2025: 0.30512352 | D2025: 0.42957817 | E2025: 0.66754894 | F2025: -0.46731993 | G2025: 0.72946873 | H2025: -0.46731993 | I2025: 0.72946873
A2026: part_time_numeric | B2026: -1.3950056 | C2026: 0.43223947 | D2026: -3.2273905 | E2026: 0.0012695135 | F2026: -2.2426939 | G2026: -0.54731724 | H2026: -2.2426939 | I2026: -0.54731724
A2027: extracurricular_numeric | B2027: -0.19052087 | C2027: 0.37810676 | D2027: -0.50388115 | E2027: 0.61440056 | F2027: -0.93204661 | G2027: 0.55100487 | H2027: -0.93204661 | I2027: 0.55100487
A2031: RESIDUAL OUTPUT | E2031: PROBABILITY OUTPUT
A2033: Observation | B2033: Predicted science_average | C2033: Residuals | E2033: Percentile | F2033: science_average
A2034: 1 | B2034: 83.819328 | C2034: -2.3193283 | E2034: 0.025 | F2034: 51.5
A2035: 2 | B2035: 88.743276 | C2035: 5.2567238 | E2035: 0.075 | F2035: 54.25
A2036: 3 | B2036: 78.2234 | C2036: 6.0265996 | E2036: 0.125 | F2036: 55.5
A2037: 4 | B2037: 77.360217 | C2037: 4.6397831 | E2037: 0.175 | F2037: 56
A2038: 5 | B2038: 79.14592 | C2038: -5.6459197 | E2038: 0.225 | F2038: 57.25
...
